<?xml version="1.0"?>
<robot name="turtlebot3_waffle_dual_lidar" xmlns:xacro="http://www.ros.org/wiki/xacro">
    
   <!-- Base Footprint -->
    <link name="base_footprint"/>

    <joint name="base_joint" type="fixed">
        <parent link="base_footprint"/>
        <child link="base_link"/>
        <origin xyz="0 0 0.010" rpy="0 0 0"/>
    </joint>

    <!-- Base Link -->
    <link name="base_link">
        <visual>
            <origin xyz="-0.064 0 0.0" rpy="0 0 0"/>
            <geometry>
                <box size="0.265 0.265 0.089"/>
            </geometry>
            <material name="light_black"/>
        </visual>
        <collision>
            <origin xyz="-0.064 0 0.0" rpy="0 0 0"/>
            <geometry>
                <box size="0.265 0.265 0.089"/>
            </geometry>
        </collision>
        <inertial>
            <origin xyz="0 0 0" rpy="0 0 0"/>
            <mass value="1.0"/>
            <inertia ixx="0.01" ixy="0.0" ixz="0.0"
                     iyy="0.01" iyz="0.0"
                     izz="0.01" />
        </inertial>
    </link>

    <!-- Wheel Joints and Links -->
    <joint name="wheel_left_joint" type="continuous">
        <parent link="base_link"/>
        <child link="wheel_left_link"/>
        <origin xyz="0 0.144 0.023" rpy="-1.57 0 0"/>
        <axis xyz="0 0 1"/>
    </joint>

    <link name="wheel_left_link">
        <visual>
            <geometry>
                <cylinder length="0.018" radius="0.033"/>
            </geometry>
            <material name="dark"/>
        </visual>
        <collision>
            <geometry>
                <cylinder length="0.018" radius="0.033"/>
            </geometry>
        </collision>
        <inertial>
            <mass value="0.05"/>
            <inertia ixx="0.001" ixy="0.0" ixz="0.0" 
                     iyy="0.001" iyz="0.0" 
                     izz="0.001"/>
        </inertial>
    </link>

    <joint name="wheel_right_joint" type="continuous">
        <parent link="base_link"/>
        <child link="wheel_right_link"/>
        <origin xyz="0 -0.144 0.023" rpy="-1.57 0 0"/>
        <axis xyz="0 0 1"/>
    </joint>

    <link name="wheel_right_link">
        <visual>
            <geometry>
                <cylinder length="0.018" radius="0.033"/>
            </geometry>
            <material name="dark"/>
        </visual>
        <collision>
            <geometry>
                <cylinder length="0.018" radius="0.033"/>
            </geometry>
        </collision>
        <inertial>
            <mass value="0.05"/>
            <inertia ixx="0.001" ixy="0.0" ixz="0.0" 
                     iyy="0.001" iyz="0.0" 
                     izz="0.001"/>
        </inertial>
    </link>

    <!-- Caster wheel -->
    <joint name="caster_back_joint" type="fixed">
        <parent link="base_link"/>
        <child link="caster_back_link"/>
        <origin xyz="-0.177 0 0.006" rpy="-1.57 0 0"/>
    </joint>

    <link name="caster_back_link">
        <collision>
            <geometry>
                <box size="0.030 0.010 0.020"/>
            </geometry>
        </collision>
        <inertial>
            <mass value="0.01"/>
            <inertia ixx="0.001" ixy="0.0" ixz="0.0" 
                     iyy="0.001" iyz="0.0" 
                     izz="0.001"/>
        </inertial>
    </link>


    <!-- Original 2D LIDAR Joint and Link -->
    <joint name="scan_joint" type="fixed">
        <parent link="base_link"/>
        <child link="base_scan"/>
        <origin xyz="-0.064 0 0.122" rpy="0 0 0"/>
    </joint>

    <link name="base_scan">
        <visual>
            <origin xyz="0 0 0" rpy="0 0 0"/>
            <geometry>
                <cylinder length="0.0315" radius="0.055"/>
            </geometry>
            <material name="dark"/>
        </visual>
        <collision>
            <origin xyz="0 0 0" rpy="0 0 0"/>
            <geometry>
                <cylinder length="0.0315" radius="0.055"/>
            </geometry>
        </collision>
        <inertial>
            <mass value="0.114" />
            <origin xyz="0 0 0" />
            <inertia ixx="0.001" ixy="0.0" ixz="0.0"
                     iyy="0.001" iyz="0.0"
                     izz="0.001" />
        </inertial>
    </link>

    <!-- 3D LIDAR Joint & Link -->
    <joint name="lidar_3d_joint" type="fixed">
        <parent link="base_link"/>
        <child link="lidar_3d"/>
        <origin xyz="-0.064 0 0.222" rpy="0 0 0"/>
    </joint>

    <link name="lidar_3d">
        <visual>
            <origin xyz="0 0 0" rpy="0 0 0"/>
            <geometry>
                <cylinder radius="0.03" length="0.05"/>
            </geometry>
            <material name="dark"/>
        </visual>
        <collision>
            <origin xyz="0 0 0" rpy="0 0 0"/>
            <geometry>
                <cylinder radius="0.03" length="0.05"/>
            </geometry>
        </collision>
        <inertial>
            <mass value="0.12"/>
            <origin xyz="0 0 0" rpy="0 0 0"/>
            <inertia ixx="0.000133333" ixy="0" ixz="0"
                     iyy="0.000133333" iyz="0"
                     izz="0.0000675"/>
        </inertial>
    </link>

    <!-- Define materials -->
    <material name="black">
        <color rgba="0.0 0.0 0.0 1.0"/>
    </material>

    <material name="dark">
        <color rgba="0.3 0.3 0.3 1.0"/>
    </material>

    <material name="light_black">
        <color rgba="0.4 0.4 0.4 1.0"/>
    </material>

    <!-- Gazebo plugin for 2D LIDAR -->
    <gazebo reference="base_scan">
        <material>Gazebo/DarkGrey</material>
    <sensor type="ray" name="velodyne_3d_sensor">
            <pose>0 0 0 0 0 0</pose>
            <visualize>false</visualize>
            <update_rate>5</update_rate>
            <ray>
                <scan>
                    <horizontal>
                        <samples>360</samples>
                        <resolution>1</resolution>
                        <min_angle>0.0</min_angle>
                        <max_angle>6.28319</max_angle>
                    </horizontal>
                </scan>
                <range>
                    <min>0.120</min>
                    <max>3.5</max>
                    <resolution>0.015</resolution>
                </range>
            </ray>
         <plugin name="gazebo_ros_velodyne_3d_controller" filename="libgazebo_ros_velodyne_laser.so">
            <ros>
                <namespace>/</namespace>
                <remapping>~/out:=scan_3d</remapping>
            </ros>
            <frame_name>lidar_3d</frame_name>
            <organize_cloud>true</organize_cloud>
            <min_range>0.1</min_range>
            <max_range>30.0</max_range>
            <gaussian_noise>0.008</gaussian_noise>
        </plugin>
    </sensor>
    </gazebo>

  <!-- 3D LIDAR Gazebo Plugin -->
    <gazebo reference="lidar_3d">
        <material>Gazebo/DarkGrey</material>
        <sensor type="ray" name="lidar_3d_sensor">
            <pose>0 0 0 0 0 0</pose>
            <visualize>true</visualize>
            <update_rate>10</update_rate>
            <ray>
                <scan>
                    <horizontal>
                        <samples>360</samples>
                        <resolution>1</resolution>
                        <min_angle>-3.14159</min_angle>
                        <max_angle>3.14159</max_angle>
                    </horizontal>
                    <vertical>
                        <samples>16</samples>
                        <resolution>1</resolution>
                        <min_angle>-0.2617994</min_angle>
                        <max_angle>0.2617994</max_angle>
                    </vertical>
                </scan>
                <range>
                    <min>0.1</min>
                    <max>30.0</max>
                    <resolution>0.01</resolution>
                </range>
            </ray>
            <plugin name="gazebo_ros_lidar3d_controller" filename="libgazebo_ros_ray_sensor.so">
                <ros>
                    <namespace>/</namespace>
                    <remapping>~/out:=scan_3d</remapping>
                </ros>
                <frame_name>lidar_3d</frame_name>
                <organize_cloud>true</organize_cloud>
                <output_type>sensor_msgs/PointCloud2</output_type>
                <min_range>0.1</min_range>
                <max_range>30.0</max_range>
            </plugin>
        </sensor>
    </gazebo>

    <!-- Define materials -->
    <material name="black">
        <color rgba="0.0 0.0 0.0 1.0"/>
    </material>

    <material name="dark">
        <color rgba="0.3 0.3 0.3 1.0"/>
    </material>

    <material name="light_black">
        <color rgba="0.4 0.4 0.4 1.0"/>
    </material>

</robot>